<?xml version="1.0" encoding="utf-8"?><testsuites><testsuite name="pytest" errors="0" failures="2" skipped="0" tests="12" time="1.715" timestamp="2025-06-05T21:08:41.134588+09:00" hostname="osakatatsuhikonoMac-mini.local"><testcase classname="tests.test_main.TestMainAppConfiguration" name="test_app_creation" time="0.386" /><testcase classname="tests.test_main.TestMainAppConfiguration" name="test_cors_origins_from_env" time="0.013"><failure message="AssertionError: assert 'https://test.com' in ['https://nextjs-app-khaki-two.vercel.app', 'http://localhost:3000', 'http://127.0.0.1:8000', 'https://example.com']">tests/test_main.py:56: in test_cors_origins_from_env
    assert "https://test.com" in allowed_origins
E   AssertionError: assert 'https://test.com' in ['https://nextjs-app-khaki-two.vercel.app', 'http://localhost:3000', 'http://127.0.0.1:8000', 'https://example.com']</failure></testcase><testcase classname="tests.test_main.TestMainAppConfiguration" name="test_cors_fallback_when_no_origins" time="0.014" /><testcase classname="tests.test_main.TestMainAppConfiguration" name="test_cors_with_pytest_environment" time="0.012" /><testcase classname="tests.test_main.TestCORSMiddleware" name="test_cors_middleware_configuration" time="0.012" /><testcase classname="tests.test_main.TestExceptionHandler" name="test_email_validation_error_handler" time="0.002" /><testcase classname="tests.test_main.TestExceptionHandler" name="test_general_validation_error_handler" time="0.002" /><testcase classname="tests.test_main.TestExceptionHandler" name="test_email_error_detection_logic" time="0.038" /><testcase classname="tests.test_main.TestRouterInclusion" name="test_routers_included" time="0.013" /><testcase classname="tests.test_main.TestDatabaseInitialization" name="test_database_tables_creation" time="0.012"><failure message="AssertionError: expected call not found.&#10;Expected: create_all(&lt;MagicMock name='engine' id='4410989200'&gt;)&#10;  Actual: create_all(Engine(sqlite:///blog.db))">tests/test_main.py:322: in test_database_tables_creation
    mock_create_all.assert_called_with(mock_engine)
/opt/homebrew/Cellar/python@3.11/3.11.11/Frameworks/Python.framework/Versions/3.11/lib/python3.11/unittest/mock.py:939: in assert_called_with
    raise AssertionError(_error_message()) from cause
E   AssertionError: expected call not found.
E   Expected: create_all(&lt;MagicMock name='engine' id='4410989200'&gt;)
E     Actual: create_all(Engine(sqlite:///blog.db))</failure></testcase><testcase classname="tests.test_main.TestApplicationIntegration" name="test_app_startup_flow" time="0.012" /><testcase classname="tests.test_main.TestApplicationIntegration" name="test_environment_variable_handling" time="0.034" /></testsuite></testsuites>