<?xml version="1.0" encoding="utf-8"?><testsuites><testsuite name="pytest" errors="0" failures="3" skipped="0" tests="12" time="2.208" timestamp="2025-06-05T20:49:38.897646+09:00" hostname="osakatatsuhikonoMac-mini.local"><testcase classname="tests.test_main.TestMainAppConfiguration" name="test_app_creation" time="0.518" /><testcase classname="tests.test_main.TestMainAppConfiguration" name="test_cors_origins_from_env" time="0.022"><failure message="AssertionError: Expected 'create_logger' to have been called.">tests/test_main.py:47: in test_cors_origins_from_env
    mock_logger.assert_called()
/opt/homebrew/Cellar/python@3.11/3.11.11/Frameworks/Python.framework/Versions/3.11/lib/python3.11/unittest/mock.py:908: in assert_called
    raise AssertionError(msg)
E   AssertionError: Expected 'create_logger' to have been called.</failure></testcase><testcase classname="tests.test_main.TestMainAppConfiguration" name="test_cors_fallback_when_no_origins" time="0.015"><failure message="AssertionError: Expected 'create_error_logger' to have been called.">tests/test_main.py:70: in test_cors_fallback_when_no_origins
    mock_error_logger.assert_called()
/opt/homebrew/Cellar/python@3.11/3.11.11/Frameworks/Python.framework/Versions/3.11/lib/python3.11/unittest/mock.py:908: in assert_called
    raise AssertionError(msg)
E   AssertionError: Expected 'create_error_logger' to have been called.</failure></testcase><testcase classname="tests.test_main.TestMainAppConfiguration" name="test_cors_with_pytest_environment" time="0.015" /><testcase classname="tests.test_main.TestCORSMiddleware" name="test_cors_middleware_configuration" time="0.015" /><testcase classname="tests.test_main.TestExceptionHandler" name="test_email_validation_error_handler" time="0.002" /><testcase classname="tests.test_main.TestExceptionHandler" name="test_general_validation_error_handler" time="0.002" /><testcase classname="tests.test_main.TestExceptionHandler" name="test_email_error_detection_logic" time="0.016" /><testcase classname="tests.test_main.TestRouterInclusion" name="test_routers_included" time="0.015" /><testcase classname="tests.test_main.TestDatabaseInitialization" name="test_database_tables_creation" time="0.043"><failure message="AssertionError: expected call not found.&#10;Expected: create_all(&lt;MagicMock name='engine' id='4420157840'&gt;)&#10;  Actual: not called.">tests/test_main.py:315: in test_database_tables_creation
    mock_base.metadata.create_all.assert_called_with(mock_engine)
/opt/homebrew/Cellar/python@3.11/3.11.11/Frameworks/Python.framework/Versions/3.11/lib/python3.11/unittest/mock.py:930: in assert_called_with
    raise AssertionError(error_message)
E   AssertionError: expected call not found.
E   Expected: create_all(&lt;MagicMock name='engine' id='4420157840'&gt;)
E     Actual: not called.</failure></testcase><testcase classname="tests.test_main.TestApplicationIntegration" name="test_app_startup_flow" time="0.014" /><testcase classname="tests.test_main.TestApplicationIntegration" name="test_environment_variable_handling" time="0.038" /></testsuite></testsuites>