2025-04-12 14:21:01,361 - app_logger - ERROR - .envファイルが見つかりません: /Users/tatu/Documents/GitHub/blog-site/venv/.env [custom_logger.py:75]
2025-04-12 14:21:01,361 - app_logger - ERROR - データベース接続に失敗しました: DATABASE_URLが設定されていません。 [custom_logger.py:75]
2025-04-12 14:23:30,930 - app_logger - ERROR - .envファイルが見つかりません: /Users/tatu/Documents/GitHub/blog-site/venv/.env [custom_logger.py:75]
2025-04-12 14:23:30,930 - app_logger - ERROR - データベース接続に失敗しました: DATABASE_URLが設定されていません。 [custom_logger.py:75]
2025-04-12 14:28:13,752 - app_logger - ERROR - .envファイルが見つかりません: /Users/tatu/Documents/GitHub/blog-site/venv/.env [custom_logger.py:75]
2025-04-12 14:28:13,752 - app_logger - ERROR - データベース接続に失敗しました: DATABASE_URLが設定されていません。 [custom_logger.py:75]
2025-04-12 14:30:43,675 - app_logger - ERROR - .envファイルが見つかりません: /Users/tatu/Documents/GitHub/blog-site/venv/.env [custom_logger.py:75]
2025-04-12 14:30:43,675 - app_logger - ERROR - データベース接続に失敗しました: DATABASE_URLが設定されていません。 [custom_logger.py:75]
2025-04-12 14:32:55,380 - app_logger - ERROR - Noneが環境変数に設定されていません。 [custom_logger.py:75]
2025-04-12 14:32:55,381 - app_logger - ERROR - DATABASE_URLが環境変数に設定されていません。 [custom_logger.py:75]
2025-04-12 14:32:55,381 - app_logger - ERROR - データベース接続に失敗しました: DATABASE_URLが設定されていません。 [custom_logger.py:75]
2025-04-12 17:52:55,343 - app_logger - ERROR - .envファイルの読み込みに失敗しました [custom_logger.py:75]
2025-04-12 17:59:44,979 - app_logger - ERROR - .envファイルの読み込みに失敗しました [custom_logger.py:75]
2025-04-12 18:03:27,935 - app_logger - ERROR - .envファイルの読み込みに失敗しました [custom_logger.py:75]
2025-04-12 18:09:22,691 - app_logger - ERROR - .envファイルが見つかりません: /Users/tatu/Documents/GitHub/blog-site/venv/.env [custom_logger.py:75]
2025-04-12 18:13:13,773 - app_logger - ERROR - .envファイルが見つかりません: /Users/tatu/Documents/GitHub/blog-site/venv/.env [custom_logger.py:75]
2025-04-12 18:15:32,789 - app_logger - ERROR - .envファイルが見つかりません: /Users/tatu/Documents/GitHub/blog-site/venv/.env [custom_logger.py:75]
------------------------------------------------------------------------------------------------------
2025-04-13 16:55:11,636 - app_logger - ERROR - .envファイルの読み込みに失敗しました: name 'env_file' is not defined [custom_logger.py:75]
2025-04-13 17:22:00,493 - app_logger - ERROR - .envファイルの読み込みに失敗しました: 'module' object is not callable [custom_logger.py:75]
-------------------------------------------------------------------------------------------------------------------------------------
2025-04-14 11:15:27,008 - app_logger - ERROR - 環境変数の取得に失敗しました。 [custom_logger.py:75]
2025-04-14 11:16:58,680 - app_logger - ERROR - 環境変数の取得に失敗しました。 [custom_logger.py:75]
2025-04-14 11:19:09,376 - app_logger - ERROR - 環境変数の取得に失敗しました。 [custom_logger.py:75]
2025-04-14 11:20:50,683 - app_logger - ERROR - 環境変数の取得に失敗しました。 [custom_logger.py:75]
2025-04-14 11:25:40,894 - app_logger - ERROR - 環境変数の取得に失敗しました。 [custom_logger.py:75]
2025-04-14 11:28:39,110 - app_logger - ERROR - 環境変数の取得に失敗しました。 [custom_logger.py:75]
2025-04-14 11:33:32,078 - app_logger - ERROR - 環境変数の取得に失敗しました。 [custom_logger.py:75]
2025-04-14 11:35:10,543 - app_logger - ERROR - 環境変数の取得に失敗しました。 [custom_logger.py:75]
2025-04-14 11:53:56,520 - app_logger - ERROR - 環境変数の取得に失敗しました。 [custom_logger.py:75]
2025-04-14 11:58:52,459 - app_logger - ERROR - 環境変数の取得に失敗しました。 [custom_logger.py:75]
2025-04-14 12:14:13,837 - app_logger - ERROR - 環境変数 DATABASE_URL が設定されていません。 [custom_logger.py:75]
2025-04-14 12:16:35,361 - app_logger - ERROR - 環境変数 DATABASE_URL が設定されていません。 [custom_logger.py:75]
2025-04-14 12:31:20,581 - app_logger - ERROR - 環境変数 DATABASE_URL が設定されていません。 [custom_logger.py:75]
2025-04-14 15:37:09,188 - app_logger - ERROR - .envファイルが見つかりません: /Users/tatu/Documents/GitHub/blog-site/venv/.env [custom_logger.py:75]
2025-04-14 15:38:11,457 - app_logger - ERROR - .envファイルが見つかりません: /Users/tatu/Documents/GitHub/blog-site/venv/.env [custom_logger.py:75]
2025-04-14 15:38:11,459 - app_logger - ERROR - ファイルIDが取得できませんでした。 [custom_logger.py:75]
2025-04-14 15:38:11,459 - app_logger - ERROR - DB_URLが取得できませんでした。 [custom_logger.py:75]
2025-04-14 15:38:11,459 - app_logger - ERROR - 環境変数の取得に失敗しました。 [custom_logger.py:75]
2025-04-14 15:39:17,412 - app_logger - ERROR - .envファイルが見つかりません: /Users/tatu/Documents/GitHub/blog-site/venv/.env [custom_logger.py:75]
2025-04-14 15:39:54,960 - app_logger - ERROR - .envファイルが見つかりません: /Users/tatu/Documents/GitHub/blog-site/venv/.env [custom_logger.py:75]
2025-04-14 15:39:54,961 - app_logger - ERROR - ファイルIDが取得できませんでした。 [custom_logger.py:75]
2025-04-14 15:39:54,961 - app_logger - ERROR - DB_URLが取得できませんでした。 [custom_logger.py:75]
2025-04-14 15:39:54,961 - app_logger - ERROR - 環境変数の取得に失敗しました。 [custom_logger.py:75]
2025-04-14 17:00:51,486 - app_logger - ERROR - データベース接続に失敗しました: not enough values to unpack (expected 3, got 0) [custom_logger.py:75]
2025-04-14 17:02:51,144 - app_logger - ERROR - データベース接続に失敗しました: not enough values to unpack (expected 3, got 0) [custom_logger.py:75]
2025-04-15 14:40:43,705 - app_logger - ERROR - DATABASE_URLが設定されていません。 [custom_logger.py:75]
2025-04-15 14:40:43,705 - app_logger - ERROR - データベース接続に失敗しました。: DATABASE_URLが設定されていません。 [custom_logger.py:75]
2025-04-15 14:44:54,898 - app_logger - ERROR - DATABASE_URLが設定されていません。 [custom_logger.py:75]
2025-04-15 14:44:54,899 - app_logger - ERROR - データベース接続に失敗しました。: DATABASE_URLが設定されていません。 [custom_logger.py:75]
2025-04-15 14:46:00,191 - app_logger - ERROR - DATABASE_URLが設定されていません。 [custom_logger.py:75]
2025-04-15 14:46:00,192 - app_logger - ERROR - データベース接続に失敗しました。: DATABASE_URLが設定されていません。 [custom_logger.py:75]
2025-04-15 15:05:05,731 - app_logger - ERROR - DATABASE_URLが設定されていません。 [custom_logger.py:75]
2025-04-15 15:05:05,731 - app_logger - ERROR - データベース接続に失敗しました。: DATABASE_URLが設定されていません。 [custom_logger.py:75]
2025-04-15 15:07:04,606 - app_logger - ERROR - DATABASE_URLが設定されていません。 [custom_logger.py:75]
2025-04-15 15:07:04,607 - app_logger - ERROR - データベース接続に失敗しました。: DATABASE_URLが設定されていません。 [custom_logger.py:75]
2025-04-15 15:59:46,807 - app_logger - ERROR - DATABASE_URLが設定されていません。 [custom_logger.py:75]
2025-04-15 15:59:46,807 - app_logger - ERROR - データベース接続に失敗しました。: DATABASE_URLが設定されていません。 [custom_logger.py:75]
2025-04-15 16:07:16,588 - app_logger - ERROR - DATABASE_URLが設定されていません。 [custom_logger.py:75]
2025-04-15 16:07:16,589 - app_logger - ERROR - データベース接続に失敗しました。: DATABASE_URLが設定されていません。 [custom_logger.py:75]
2025-04-15 16:08:16,003 - app_logger - ERROR - DATABASE_URLが設定されていません。 [custom_logger.py:75]
2025-04-15 16:08:16,004 - app_logger - ERROR - データベース接続に失敗しました。: DATABASE_URLが設定されていません。 [custom_logger.py:75]
2025-04-15 16:10:34,570 - app_logger - ERROR - DATABASE_URLが設定されていません。 [custom_logger.py:75]
2025-04-15 16:10:34,571 - app_logger - ERROR - データベース接続に失敗しました。: DATABASE_URLが設定されていません。 [custom_logger.py:75]
2025-04-15 16:13:06,331 - app_logger - ERROR - DATABASE_URLが設定されていません。 [custom_logger.py:75]
2025-04-15 16:13:06,332 - app_logger - ERROR - データベース接続に失敗しました。: DATABASE_URLが設定されていません。 [custom_logger.py:75]
2025-04-15 16:13:51,816 - app_logger - ERROR - DATABASE_URLが設定されていません。 [custom_logger.py:75]
2025-04-15 16:13:51,817 - app_logger - ERROR - データベース接続に失敗しました。: DATABASE_URLが設定されていません。 [custom_logger.py:75]
2025-04-15 16:15:46,928 - app_logger - ERROR - DATABASE_URLが設定されていません。 [custom_logger.py:75]
2025-04-15 16:15:46,929 - app_logger - ERROR - データベース接続に失敗しました。: DATABASE_URLが設定されていません。 [custom_logger.py:75]
2025-04-15 16:16:30,785 - app_logger - ERROR - DATABASE_URLが設定されていません。 [custom_logger.py:75]
2025-04-15 16:16:30,786 - app_logger - ERROR - データベース接続に失敗しました。: DATABASE_URLが設定されていません。 [custom_logger.py:75]
2025-04-15 16:17:32,155 - app_logger - ERROR - DATABASE_URLが設定されていません。 [custom_logger.py:75]
2025-04-15 16:17:32,156 - app_logger - ERROR - データベース接続に失敗しました。: DATABASE_URLが設定されていません。 [custom_logger.py:75]
2025-04-15 16:19:52,788 - app_logger - ERROR - DATABASE_URLが設定されていません。 [custom_logger.py:75]
2025-04-15 16:19:52,788 - app_logger - ERROR - データベース接続に失敗しました。: DATABASE_URLが設定されていません。 [custom_logger.py:75]
2025-04-15 16:27:54,146 - app_logger - ERROR - DATABASE_URLが設定されていません。 [custom_logger.py:75]
2025-04-15 16:27:54,146 - app_logger - ERROR - データベース接続に失敗しました。: DATABASE_URLが設定されていません。 [custom_logger.py:75]
2025-04-15 16:44:36,535 - app_logger - ERROR - DATABASE_URLが設定されていません。 [custom_logger.py:75]
2025-04-15 16:44:36,537 - app_logger - ERROR - データベース接続に失敗しました。: DATABASE_URLが設定されていません。 [custom_logger.py:75]
2025-04-15 16:46:01,681 - app_logger - ERROR - DATABASE_URLが設定されていません。 [custom_logger.py:75]
2025-04-15 16:46:01,684 - app_logger - ERROR - データベース接続に失敗しました。: DATABASE_URLが設定されていません。 [custom_logger.py:75]
2025-04-15 16:49:00,655 - app_logger - ERROR - DATABASE_URLが設定されていません。 [custom_logger.py:75]
2025-04-15 16:49:00,656 - app_logger - ERROR - データベース接続に失敗しました。: DATABASE_URLが設定されていません。 [custom_logger.py:75]
2025-04-15 16:49:29,555 - app_logger - ERROR - DATABASE_URLが設定されていません。 [custom_logger.py:75]
2025-04-15 16:49:29,555 - app_logger - ERROR - データベース接続に失敗しました。: DATABASE_URLが設定されていません。 [custom_logger.py:75]
2025-04-15 16:56:30,352 - app_logger - ERROR - DATABASE_URLが設定されていません。 [custom_logger.py:75]
2025-04-15 16:56:30,353 - app_logger - ERROR - データベース接続に失敗しました。: DATABASE_URLが設定されていません。 [custom_logger.py:75]
2025-04-15 16:59:22,819 - app_logger - ERROR - DATABASE_URLが設定されていません。 [custom_logger.py:75]
2025-04-15 16:59:22,820 - app_logger - ERROR - データベース接続に失敗しました。: DATABASE_URLが設定されていません。 [custom_logger.py:75]
2025-04-15 16:59:55,319 - app_logger - ERROR - DATABASE_URLが設定されていません。 [custom_logger.py:75]
2025-04-15 16:59:55,320 - app_logger - ERROR - データベース接続に失敗しました。: DATABASE_URLが設定されていません。 [custom_logger.py:75]
2025-04-15 17:00:35,870 - app_logger - ERROR - DATABASE_URLが設定されていません。 [custom_logger.py:75]
2025-04-15 17:00:35,870 - app_logger - ERROR - データベース接続に失敗しました。: DATABASE_URLが設定されていません。 [custom_logger.py:75]
2025-04-15 17:02:37,416 - app_logger - ERROR - DATABASE_URLが設定されていません。 [custom_logger.py:75]
2025-04-15 17:02:37,417 - app_logger - ERROR - データベース接続に失敗しました。: DATABASE_URLが設定されていません。 [custom_logger.py:75]
2025-04-15 17:07:01,101 - app_logger - ERROR - DATABASE_URLが設定されていません。 [custom_logger.py:75]
2025-04-15 17:07:01,102 - app_logger - ERROR - データベース接続に失敗しました。: DATABASE_URLが設定されていません。 [custom_logger.py:75]
2025-04-15 17:10:15,188 - app_logger - ERROR - DATABASE_URLが設定されていません。 [custom_logger.py:75]
2025-04-15 17:10:15,189 - app_logger - ERROR - データベース接続に失敗しました。: DATABASE_URLが設定されていません。 [custom_logger.py:75]
--------------------------------------------------------------------------------------------------------------------------------------
2025-04-16 10:21:41,044 - app_logger - ERROR - 記事の作成に失敗しました。: (sqlite3.IntegrityError) UNIQUE constraint failed: articles.id
[SQL: INSERT INTO articles (id, title, body) VALUES (?, ?, ?)]
[parameters: (0, 'string', 'string')]
(Background on this error at: https://sqlalche.me/e/20/gkpj) [custom_logger.py:75]
2025-04-16 10:21:41,046 - app_logger - ERROR - DBセッションのコミットに失敗しました。: (sqlite3.IntegrityError) UNIQUE constraint failed: articles.id
[SQL: INSERT INTO articles (id, title, body) VALUES (?, ?, ?)]
[parameters: (0, 'string', 'string')]
(Background on this error at: https://sqlalche.me/e/20/gkpj) [custom_logger.py:75]
2025-04-16 10:21:53,712 - app_logger - ERROR - 記事の作成に失敗しました。: (sqlite3.IntegrityError) UNIQUE constraint failed: articles.id
[SQL: INSERT INTO articles (id, title, body) VALUES (?, ?, ?)]
[parameters: (1, 'string1', 'string1')]
(Background on this error at: https://sqlalche.me/e/20/gkpj) [custom_logger.py:75]
2025-04-16 10:21:53,714 - app_logger - ERROR - DBセッションのコミットに失敗しました。: (sqlite3.IntegrityError) UNIQUE constraint failed: articles.id
[SQL: INSERT INTO articles (id, title, body) VALUES (?, ?, ?)]
[parameters: (1, 'string1', 'string1')]
(Background on this error at: https://sqlalche.me/e/20/gkpj) [custom_logger.py:75]
2025-04-16 10:24:19,088 - app_logger - ERROR - 記事の作成に失敗しました。: (sqlite3.IntegrityError) UNIQUE constraint failed: articles.id
[SQL: INSERT INTO articles (id, title, body) VALUES (?, ?, ?)]
[parameters: (1, 'string1', 'string')]
(Background on this error at: https://sqlalche.me/e/20/gkpj) [custom_logger.py:75]
2025-04-16 10:24:19,088 - app_logger - ERROR - DBセッションのコミットに失敗しました。: (sqlite3.IntegrityError) UNIQUE constraint failed: articles.id
[SQL: INSERT INTO articles (id, title, body) VALUES (?, ?, ?)]
[parameters: (1, 'string1', 'string')]
(Background on this error at: https://sqlalche.me/e/20/gkpj) [custom_logger.py:75]
2025-04-16 10:26:22,965 - app_logger - ERROR - 記事の作成に失敗しました。: (sqlite3.IntegrityError) UNIQUE constraint failed: articles.id
[SQL: INSERT INTO articles (id, title, body) VALUES (?, ?, ?)]
[parameters: (1, 'string1', 'string')]
(Background on this error at: https://sqlalche.me/e/20/gkpj) [custom_logger.py:75]
2025-04-16 10:26:22,966 - app_logger - ERROR - DBセッションのコミットに失敗しました。: (sqlite3.IntegrityError) UNIQUE constraint failed: articles.id
[SQL: INSERT INTO articles (id, title, body) VALUES (?, ?, ?)]
[parameters: (1, 'string1', 'string')]
(Background on this error at: https://sqlalche.me/e/20/gkpj) [custom_logger.py:75]
2025-04-16 10:56:43,372 - app_logger - ERROR - 記事の作成に失敗しました。: (sqlite3.IntegrityError) UNIQUE constraint failed: articles.id
[SQL: INSERT INTO articles (id, title, body) VALUES (?, ?, ?)]
[parameters: (1, 'string1', 'string')]
(Background on this error at: https://sqlalche.me/e/20/gkpj) [custom_logger.py:75]
2025-04-16 10:56:43,373 - app_logger - ERROR - DBセッションのコミットに失敗しました。: (sqlite3.IntegrityError) UNIQUE constraint failed: articles.id
[SQL: INSERT INTO articles (id, title, body) VALUES (?, ?, ?)]
[parameters: (1, 'string1', 'string')]
(Background on this error at: https://sqlalche.me/e/20/gkpj) [custom_logger.py:75]
2025-04-16 14:39:22,922 - app_logger - ERROR - タイトルは30文字以内で入力してください。 [custom_logger.py:75]
2025-04-16 14:39:23,235 - app_logger - ERROR - タイトルは30文字以内で入力してください。 [custom_logger.py:75]
2025-04-16 14:39:26,418 - app_logger - ERROR - タイトルは30文字以内で入力してください。 [custom_logger.py:75]
2025-04-16 14:39:30,638 - app_logger - ERROR - タイトルは30文字以内で入力してください。 [custom_logger.py:75]
2025-04-16 14:39:32,196 - app_logger - ERROR - タイトルは30文字以内で入力してください。 [custom_logger.py:75]
2025-04-16 14:39:32,196 - app_logger - ERROR - 本文は100文字以内で入力してください。 [custom_logger.py:75]
2025-04-16 14:39:36,261 - app_logger - ERROR - タイトルは30文字以内で入力してください。 [custom_logger.py:75]
2025-04-16 14:39:36,261 - app_logger - ERROR - 本文は100文字以内で入力してください。 [custom_logger.py:75]
2025-04-16 14:39:40,020 - app_logger - ERROR - タイトルは30文字以内で入力してください。 [custom_logger.py:75]
2025-04-16 14:39:40,020 - app_logger - ERROR - 本文は100文字以内で入力してください。 [custom_logger.py:75]
2025-04-16 14:40:50,692 - app_logger - ERROR - 本文は100文字以内で入力してください。 [custom_logger.py:75]
2025-04-16 14:40:54,702 - app_logger - ERROR - 本文は100文字以内で入力してください。 [custom_logger.py:75]
---------------------------------------------------------------------------------------------------------------------------------------
2025-04-16 16:13:33,853 - app_logger - ERROR - titleの検証エラー: String should have at most 30 characters [custom_logger.py:75]
2025-04-16 16:15:04,995 - app_logger - ERROR - の検証エラー: String should have at most 50 characters [custom_logger.py:75]
2025-04-16 16:17:13,998 - app_logger - ERROR - の検証エラー: String should have at most 50 characters [custom_logger.py:75]
2025-04-16 16:21:08,637 - app_logger - ERROR - bodyの検証エラー: String should have at most 50 characters [custom_logger.py:75]
2025-04-16 16:21:32,060 - app_logger - ERROR - titleの検証エラー: String should have at most 30 characters [custom_logger.py:75]
2025-04-16 16:21:32,060 - app_logger - ERROR - bodyの検証エラー: String should have at most 50 characters [custom_logger.py:75]
