# テスト実行レポート

## 📊 基本情報
- **実行日時**: 2025-06-05T20:50:38.555571
- **テストID**: 20250605_205038
- **テスト対象**: test_main
- **テストファイル**: tests/test_main.py

## 🧪 テスト結果サマリー

| 項目 | 値 |
|------|-----|
| 総テスト数 | 12 |
| 成功 | 9 |
| 失敗 | 3 |
| エラー | 0 |
| スキップ | 0 |
| 成功率 | 75.00% |
| 実行時間 | 1.654秒 |

## 📈 カバレッジ結果

| 項目 | 値 |
|------|-----|
| 全体カバレッジ | 17.73% |
| 総ステートメント数 | 3204 |
| カバー済みステートメント | 568 |
| 未カバーステートメント | 2636 |
| 除外ステートメント | 0 |


## ❌ 失敗したテスト

### 1. test_cors_origins_from_env
- **クラス**: tests.test_main.TestMainAppConfiguration
- **ステータス**: failed
- **実行時間**: 0.013秒
- **失敗メッセージ**: AssertionError: expected call not found.
Expected: create_logger('CORS_ORIGIN -> OK')
  Actual: not called.
```
tests/test_main.py:47: in test_cors_origins_from_env
    mock_logger.assert_called_with(f"CORS_ORIGIN -> OK")
/opt/homebrew/Cellar/python@3.11/3.11.11/Frameworks/Python.framework/Versions/3.11/lib/python3.11/unittest/mock.py:930: in assert_called_with
    raise AssertionError(error_message)
E   AssertionError: expected call not found.
E   Expected: create_logger('CORS_ORIGIN -> OK')
E     Actual: not called.
```

### 2. test_cors_fallback_when_no_origins
- **クラス**: tests.test_main.TestMainAppConfiguration
- **ステータス**: failed
- **実行時間**: 0.013秒
- **失敗メッセージ**: AssertionError: expected call not found.
Expected: create_error_logger('CORS_ORIGINSとLOCAL_ORIGINの両方が取得できませんでした。')
  Actual: not called.
```
tests/test_main.py:68: in test_cors_fallback_when_no_origins
    mock_error_logger.assert_called_with("CORS_ORIGINSとLOCAL_ORIGINの両方が取得できませんでした。")
/opt/homebrew/Cellar/python@3.11/3.11.11/Frameworks/Python.framework/Versions/3.11/lib/python3.11/unittest/mock.py:930: in assert_called_with
    raise AssertionError(error_message)
E   AssertionError: expected call not found.
E   Expected: create_error_logger('CORS_ORIGINSとLOCAL_ORIGINの両方が取得できませんでした。')
E     Actual: not called.
```

### 3. test_database_tables_creation
- **クラス**: tests.test_main.TestDatabaseInitialization
- **ステータス**: failed
- **実行時間**: 0.031秒
- **失敗メッセージ**: AssertionError: expected call not found.
Expected: create_all(<MagicMock name='engine' id='4421317264'>)
  Actual: not called.
```
tests/test_main.py:317: in test_database_tables_creation
    mock_metadata.create_all.assert_called_with(mock_engine)
/opt/homebrew/Cellar/python@3.11/3.11.11/Frameworks/Python.framework/Versions/3.11/lib/python3.11/unittest/mock.py:930: in assert_called_with
    raise AssertionError(error_message)
E   AssertionError: expected call not found.
E   Expected: create_all(<MagicMock name='engine' id='4421317264'>)
E     Actual: not called.
```


## 📁 ファイル別カバレッジ

| ファイル | カバレッジ | ステートメント | カバー済み | 未カバー |
|----------|------------|----------------|-----------|----------|
| custom_token.py | 26.6% | 94 | 25 | 69 |
| database.py | 66.3% | 89 | 59 | 30 |
| exceptions.py | 50.0% | 12 | 6 | 6 |
| hashing.py | 77.8% | 9 | 7 | 2 |
| logger/__init__.py | 100.0% | 0 | 0 | 0 |
| logger/custom_logger.py | 100.0% | 21 | 21 | 0 |
| main.py | 92.9% | 42 | 39 | 3 |
| models.py | 94.6% | 37 | 35 | 2 |
| oauth2.py | 35.1% | 37 | 13 | 24 |
| routers/__init__.py | 100.0% | 0 | 0 | 0 |
| routers/article.py | 18.4% | 152 | 28 | 124 |
| routers/auth.py | 36.7% | 98 | 36 | 62 |
| routers/user.py | 26.4% | 201 | 53 | 148 |
| schemas.py | 76.4% | 89 | 68 | 21 |
| test_runner_with_history.py | 0.0% | 223 | 0 | 223 |
| tests/__init__.py | 100.0% | 0 | 0 | 0 |
| tests/bug_tracker.py | 0.0% | 200 | 0 | 200 |
| tests/test_article_router.py | 100.0% | 0 | 0 | 0 |
| tests/test_auth_router.py | 100.0% | 0 | 0 | 0 |
| tests/test_custom_token.py | 0.0% | 191 | 0 | 191 |
| tests/test_database.py | 0.0% | 113 | 0 | 113 |
| tests/test_email_sender.py | 100.0% | 0 | 0 | 0 |
| tests/test_email_validator.py | 100.0% | 0 | 0 | 0 |
| tests/test_exceptions.py | 0.0% | 150 | 0 | 150 |
| tests/test_hashing.py | 100.0% | 0 | 0 | 0 |
| tests/test_integration.py | 100.0% | 0 | 0 | 0 |
| tests/test_main.py | 96.4% | 165 | 159 | 6 |
| tests/test_models.py | 0.0% | 165 | 0 | 165 |
| tests/test_oauth2.py | 0.0% | 138 | 0 | 138 |
| tests/test_routers_corrected.py | 100.0% | 0 | 0 | 0 |
| tests/test_schemas.py | 0.0% | 196 | 0 | 196 |
| tests/test_user_deletion_integration.py | 0.0% | 121 | 0 | 121 |
| tests/test_user_router.py | 0.0% | 504 | 0 | 504 |
| update_final_success.py | 0.0% | 21 | 0 | 21 |
| utils/__init__.py | 100.0% | 0 | 0 | 0 |
| utils/email_sender.py | 13.3% | 113 | 15 | 98 |
| utils/email_validator.py | 17.4% | 23 | 4 | 19 |

## 📎 生成ファイル
- **JUnit XML**: test_results_20250605_205038.xml
- **カバレッジJSON**: coverage_20250605_205038.json
- **HTMLカバレッジ**: htmlcov_20250605_205038/
