# テスト実行レポート

## 📊 基本情報
- **実行日時**: 2025-06-05T21:00:59.209433
- **テストID**: 20250605_210059
- **テスト対象**: test_user_router
- **テストファイル**: tests/test_user_router.py

## 🧪 テスト結果サマリー

| 項目 | 値 |
|------|-----|
| 総テスト数 | 44 |
| 成功 | 38 |
| 失敗 | 6 |
| エラー | 0 |
| スキップ | 0 |
| 成功率 | 86.36% |
| 実行時間 | 1.790秒 |

## 📈 カバレッジ結果

| 項目 | 値 |
|------|-----|
| 全体カバレッジ | 28.49% |
| 総ステートメント数 | 3629 |
| カバー済みステートメント | 1034 |
| 未カバーステートメント | 2595 |
| 除外ステートメント | 0 |


## ❌ 失敗したテスト

### 1. test_delete_user_account_user_not_found
- **クラス**: tests.test_user_router.TestDeleteUserAccountEndpoint
- **ステータス**: failed
- **実行時間**: 0.025秒
- **失敗メッセージ**: AssertionError: assert 500 == 404
 +  where 500 = HTTPException(status_code=500, detail='\u9000\u4f1a\u51e6\u7406\u4e2d\u306b\u4e88\u671f\u3057\u306a\u3044\u30a8\u30e9\u30fc\u304c\u767a\u751f\u3057\u307e\u3057\u305f').status_code
 +    where HTTPException(status_code=500, detail='\u9000\u4f1a\u51e6\u7406\u4e2d\u306b\u4e88\u671f\u3057\u306a\u3044\u30a8\u30e9\u30fc\u304c\u767a\u751f\u3057\u307e\u3057\u305f') = <ExceptionInfo HTTPException(status_code=500, detail='\u9000\u4f1a\u51e6\u7406\u4e2d\u306b\u4e88\u671f\u3057\u306a\u3044\u30a8\u30e9\u30fc\u304c\u767a\u751f\u3057\u307e\u3057\u305f') tblen=5>.value
 +  and   404 = status.HTTP_404_NOT_FOUND
```
tests/test_user_router.py:480: in test_delete_user_account_user_not_found
    assert exc_info.value.status_code == status.HTTP_404_NOT_FOUND
E   AssertionError: assert 500 == 404
E    +  where 500 = HTTPException(status_code=500, detail='\u9000\u4f1a\u51e6\u7406\u4e2d\u306b\u4e88\u671f\u3057\u306a\u3044\u30a8\u30e9\u30fc\u304c\u767a\u751f\u3057\u307e\u3057\u305f').status_code
E    +    where HTTPException(status_code=500, detail='\u9000\u4f1a\u51e6\u7406\u4e2d\u306b\u4e88\u671f\u3057\u306a\u3044\u30a8\u30e9\u30fc\u304c\u767a\u751f\u3057\u307e\u3057\u305f') = <ExceptionInfo HTTPException(status_code=500, detail='\u9000\u4f1a\u51e6\u7406\u4e2d\u306b\u4e88\u671f\u3057\u306a\u3044\u30a8\u30e9\u30fc\u304c\u767a\u751f\u3057\u307e\u3057\u305f') tblen=5>.value
E    +  and   404 = status.HTTP_404_NOT_FOUND
```

### 2. test_delete_user_account_no_password_set
- **クラス**: tests.test_user_router.TestDeleteUserAccountEndpoint
- **ステータス**: failed
- **実行時間**: 0.003秒
- **失敗メッセージ**: AssertionError: assert 500 == 400
 +  where 500 = HTTPException(status_code=500, detail='\u9000\u4f1a\u51e6\u7406\u4e2d\u306b\u4e88\u671f\u3057\u306a\u3044\u30a8\u30e9\u30fc\u304c\u767a\u751f\u3057\u307e\u3057\u305f').status_code
 +    where HTTPException(status_code=500, detail='\u9000\u4f1a\u51e6\u7406\u4e2d\u306b\u4e88\u671f\u3057\u306a\u3044\u30a8\u30e9\u30fc\u304c\u767a\u751f\u3057\u307e\u3057\u305f') = <ExceptionInfo HTTPException(status_code=500, detail='\u9000\u4f1a\u51e6\u7406\u4e2d\u306b\u4e88\u671f\u3057\u306a\u3044\u30a8\u30e9\u30fc\u304c\u767a\u751f\u3057\u307e\u3057\u305f') tblen=5>.value
 +  and   400 = status.HTTP_400_BAD_REQUEST
```
tests/test_user_router.py:492: in test_delete_user_account_no_password_set
    assert exc_info.value.status_code == status.HTTP_400_BAD_REQUEST
E   AssertionError: assert 500 == 400
E    +  where 500 = HTTPException(status_code=500, detail='\u9000\u4f1a\u51e6\u7406\u4e2d\u306b\u4e88\u671f\u3057\u306a\u3044\u30a8\u30e9\u30fc\u304c\u767a\u751f\u3057\u307e\u3057\u305f').status_code
E    +    where HTTPException(status_code=500, detail='\u9000\u4f1a\u51e6\u7406\u4e2d\u306b\u4e88\u671f\u3057\u306a\u3044\u30a8\u30e9\u30fc\u304c\u767a\u751f\u3057\u307e\u3057\u305f') = <ExceptionInfo HTTPException(status_code=500, detail='\u9000\u4f1a\u51e6\u7406\u4e2d\u306b\u4e88\u671f\u3057\u306a\u3044\u30a8\u30e9\u30fc\u304c\u767a\u751f\u3057\u307e\u3057\u305f') tblen=5>.value
E    +  and   400 = status.HTTP_400_BAD_REQUEST
```

### 3. test_delete_user_account_wrong_password
- **クラス**: tests.test_user_router.TestDeleteUserAccountEndpoint
- **ステータス**: failed
- **実行時間**: 0.003秒
- **失敗メッセージ**: AssertionError: assert 500 == 401
 +  where 500 = HTTPException(status_code=500, detail='\u9000\u4f1a\u51e6\u7406\u4e2d\u306b\u4e88\u671f\u3057\u306a\u3044\u30a8\u30e9\u30fc\u304c\u767a\u751f\u3057\u307e\u3057\u305f').status_code
 +    where HTTPException(status_code=500, detail='\u9000\u4f1a\u51e6\u7406\u4e2d\u306b\u4e88\u671f\u3057\u306a\u3044\u30a8\u30e9\u30fc\u304c\u767a\u751f\u3057\u307e\u3057\u305f') = <ExceptionInfo HTTPException(status_code=500, detail='\u9000\u4f1a\u51e6\u7406\u4e2d\u306b\u4e88\u671f\u3057\u306a\u3044\u30a8\u30e9\u30fc\u304c\u767a\u751f\u3057\u307e\u3057\u305f') tblen=5>.value
 +  and   401 = status.HTTP_401_UNAUTHORIZED
```
tests/test_user_router.py:508: in test_delete_user_account_wrong_password
    assert exc_info.value.status_code == status.HTTP_401_UNAUTHORIZED
E   AssertionError: assert 500 == 401
E    +  where 500 = HTTPException(status_code=500, detail='\u9000\u4f1a\u51e6\u7406\u4e2d\u306b\u4e88\u671f\u3057\u306a\u3044\u30a8\u30e9\u30fc\u304c\u767a\u751f\u3057\u307e\u3057\u305f').status_code
E    +    where HTTPException(status_code=500, detail='\u9000\u4f1a\u51e6\u7406\u4e2d\u306b\u4e88\u671f\u3057\u306a\u3044\u30a8\u30e9\u30fc\u304c\u767a\u751f\u3057\u307e\u3057\u305f') = <ExceptionInfo HTTPException(status_code=500, detail='\u9000\u4f1a\u51e6\u7406\u4e2d\u306b\u4e88\u671f\u3057\u306a\u3044\u30a8\u30e9\u30fc\u304c\u767a\u751f\u3057\u307e\u3057\u305f') tblen=5>.value
E    +  and   401 = status.HTTP_401_UNAUTHORIZED
```

### 4. test_delete_user_account_no_email
- **クラス**: tests.test_user_router.TestDeleteUserAccountEndpoint
- **ステータス**: failed
- **実行時間**: 0.003秒
- **失敗メッセージ**: AssertionError: assert 500 == 400
 +  where 500 = HTTPException(status_code=500, detail='\u9000\u4f1a\u51e6\u7406\u4e2d\u306b\u4e88\u671f\u3057\u306a\u3044\u30a8\u30e9\u30fc\u304c\u767a\u751f\u3057\u307e\u3057\u305f').status_code
 +    where HTTPException(status_code=500, detail='\u9000\u4f1a\u51e6\u7406\u4e2d\u306b\u4e88\u671f\u3057\u306a\u3044\u30a8\u30e9\u30fc\u304c\u767a\u751f\u3057\u307e\u3057\u305f') = <ExceptionInfo HTTPException(status_code=500, detail='\u9000\u4f1a\u51e6\u7406\u4e2d\u306b\u4e88\u671f\u3057\u306a\u3044\u30a8\u30e9\u30fc\u304c\u767a\u751f\u3057\u307e\u3057\u305f') tblen=5>.value
 +  and   400 = status.HTTP_400_BAD_REQUEST
```
tests/test_user_router.py:524: in test_delete_user_account_no_email
    assert exc_info.value.status_code == status.HTTP_400_BAD_REQUEST
E   AssertionError: assert 500 == 400
E    +  where 500 = HTTPException(status_code=500, detail='\u9000\u4f1a\u51e6\u7406\u4e2d\u306b\u4e88\u671f\u3057\u306a\u3044\u30a8\u30e9\u30fc\u304c\u767a\u751f\u3057\u307e\u3057\u305f').status_code
E    +    where HTTPException(status_code=500, detail='\u9000\u4f1a\u51e6\u7406\u4e2d\u306b\u4e88\u671f\u3057\u306a\u3044\u30a8\u30e9\u30fc\u304c\u767a\u751f\u3057\u307e\u3057\u305f') = <ExceptionInfo HTTPException(status_code=500, detail='\u9000\u4f1a\u51e6\u7406\u4e2d\u306b\u4e88\u671f\u3057\u306a\u3044\u30a8\u30e9\u30fc\u304c\u767a\u751f\u3057\u307e\u3057\u305f') tblen=5>.value
E    +  and   400 = status.HTTP_400_BAD_REQUEST
```

### 5. test_delete_user_account_success
- **クラス**: tests.test_user_router.TestDeleteUserAccountEndpoint
- **ステータス**: failed
- **実行時間**: 0.006秒
- **失敗メッセージ**: fastapi.exceptions.HTTPException: 500: 退会処理中に予期しないエラーが発生しました
```
routers/user.py:466: in delete_user_account
    認証ユーザー: {current_user.email}"
E   AttributeError: 'Depends' object has no attribute 'email'

During handling of the above exception, another exception occurred:
tests/test_user_router.py:562: in test_delete_user_account_success
    result = asyncio.run(delete_user_account(valid_deletion_request, mock_db))
/opt/homebrew/Cellar/python@3.11/3.11.11/Frameworks/Python.framework/Versions/3.11/lib/python3.11/asyncio/runners.py:190: in run
    return runner.run(main)
/opt/homebrew/Cellar/python@3.11/3.11.11/Frameworks/Python.framework/Versions/3.11/lib/python3.11/asyncio/runners.py:118: in run
    return self._loop.run_until_complete(task)
/opt/homebrew/Cellar/python@3.11/3.11.11/Frameworks/Python.framework/Versions/3.11/lib/python3.11/asyncio/base_events.py:654: in run_until_complete
    return future.result()
routers/user.py:569: in delete_user_account
    raise HTTPException(
E   fastapi.exceptions.HTTPException: 500: 退会処理中に予期しないエラーが発生しました
```

### 6. test_delete_user_account_password_mismatch
- **クラス**: tests.test_user_router.TestDeleteUserAccountEndpoint
- **ステータス**: failed
- **実行時間**: 0.003秒
- **失敗メッセージ**: AssertionError: assert 500 == 400
 +  where 500 = HTTPException(status_code=500, detail='\u9000\u4f1a\u51e6\u7406\u4e2d\u306b\u4e88\u671f\u3057\u306a\u3044\u30a8\u30e9\u30fc\u304c\u767a\u751f\u3057\u307e\u3057\u305f').status_code
 +    where HTTPException(status_code=500, detail='\u9000\u4f1a\u51e6\u7406\u4e2d\u306b\u4e88\u671f\u3057\u306a\u3044\u30a8\u30e9\u30fc\u304c\u767a\u751f\u3057\u307e\u3057\u305f') = <ExceptionInfo HTTPException(status_code=500, detail='\u9000\u4f1a\u51e6\u7406\u4e2d\u306b\u4e88\u671f\u3057\u306a\u3044\u30a8\u30e9\u30fc\u304c\u767a\u751f\u3057\u307e\u3057\u305f') tblen=5>.value
 +  and   400 = status.HTTP_400_BAD_REQUEST
```
tests/test_user_router.py:583: in test_delete_user_account_password_mismatch
    assert exc_info.value.status_code == status.HTTP_400_BAD_REQUEST
E   AssertionError: assert 500 == 400
E    +  where 500 = HTTPException(status_code=500, detail='\u9000\u4f1a\u51e6\u7406\u4e2d\u306b\u4e88\u671f\u3057\u306a\u3044\u30a8\u30e9\u30fc\u304c\u767a\u751f\u3057\u307e\u3057\u305f').status_code
E    +    where HTTPException(status_code=500, detail='\u9000\u4f1a\u51e6\u7406\u4e2d\u306b\u4e88\u671f\u3057\u306a\u3044\u30a8\u30e9\u30fc\u304c\u767a\u751f\u3057\u307e\u3057\u305f') = <ExceptionInfo HTTPException(status_code=500, detail='\u9000\u4f1a\u51e6\u7406\u4e2d\u306b\u4e88\u671f\u3057\u306a\u3044\u30a8\u30e9\u30fc\u304c\u767a\u751f\u3057\u307e\u3057\u305f') tblen=5>.value
E    +  and   400 = status.HTTP_400_BAD_REQUEST
```


## 📁 ファイル別カバレッジ

| ファイル | カバレッジ | ステートメント | カバー済み | 未カバー |
|----------|------------|----------------|-----------|----------|
| custom_token.py | 26.6% | 94 | 25 | 69 |
| database.py | 66.3% | 89 | 59 | 30 |
| exceptions.py | 50.0% | 12 | 6 | 6 |
| hashing.py | 77.8% | 9 | 7 | 2 |
| logger/__init__.py | 100.0% | 0 | 0 | 0 |
| logger/custom_logger.py | 100.0% | 21 | 21 | 0 |
| main.py | 66.7% | 42 | 28 | 14 |
| models.py | 94.6% | 37 | 35 | 2 |
| oauth2.py | 35.1% | 37 | 13 | 24 |
| routers/__init__.py | 100.0% | 0 | 0 | 0 |
| routers/article.py | 18.4% | 152 | 28 | 124 |
| routers/auth.py | 36.7% | 98 | 36 | 62 |
| routers/user.py | 97.0% | 201 | 195 | 6 |
| schemas.py | 79.8% | 89 | 71 | 18 |
| test_runner_with_history.py | 0.0% | 223 | 0 | 223 |
| tests/__init__.py | 100.0% | 0 | 0 | 0 |
| tests/bug_tracker.py | 0.0% | 200 | 0 | 200 |
| tests/test_article_router.py | 0.0% | 252 | 0 | 252 |
| tests/test_auth_router.py | 0.0% | 175 | 0 | 175 |
| tests/test_custom_token.py | 0.0% | 191 | 0 | 191 |
| tests/test_database.py | 0.0% | 113 | 0 | 113 |
| tests/test_email_sender.py | 100.0% | 0 | 0 | 0 |
| tests/test_email_validator.py | 100.0% | 0 | 0 | 0 |
| tests/test_exceptions.py | 0.0% | 150 | 0 | 150 |
| tests/test_hashing.py | 100.0% | 0 | 0 | 0 |
| tests/test_integration.py | 100.0% | 0 | 0 | 0 |
| tests/test_main.py | 0.0% | 163 | 0 | 163 |
| tests/test_models.py | 0.0% | 165 | 0 | 165 |
| tests/test_oauth2.py | 0.0% | 138 | 0 | 138 |
| tests/test_routers_corrected.py | 100.0% | 0 | 0 | 0 |
| tests/test_schemas.py | 0.0% | 196 | 0 | 196 |
| tests/test_user_deletion_integration.py | 0.0% | 121 | 0 | 121 |
| tests/test_user_router.py | 97.4% | 504 | 491 | 13 |
| update_final_success.py | 0.0% | 21 | 0 | 21 |
| utils/__init__.py | 100.0% | 0 | 0 | 0 |
| utils/email_sender.py | 13.3% | 113 | 15 | 98 |
| utils/email_validator.py | 17.4% | 23 | 4 | 19 |

## 📎 生成ファイル
- **JUnit XML**: test_results_20250605_210059.xml
- **カバレッジJSON**: coverage_20250605_210059.json
- **HTMLカバレッジ**: htmlcov_20250605_210059/
