# テスト実行レポート

## 📊 基本情報
- **実行日時**: 2025-06-06T12:23:29.032770
- **テストID**: 20250606_122329
- **テスト対象**: all_tests
- **テストファイル**: tests/

## 🧪 テスト結果サマリー

| 項目 | 値 |
|------|-----|
| 総テスト数 | 300 |
| 成功 | 294 |
| 失敗 | 6 |
| エラー | 0 |
| スキップ | 0 |
| 成功率 | 98.00% |
| 実行時間 | 2.305秒 |

## 📈 カバレッジ結果

| 項目 | 値 |
|------|-----|
| 全体カバレッジ | 97.79% |
| 総ステートメント数 | 1043 |
| カバー済みステートメント | 1020 |
| 未カバーステートメント | 23 |
| 除外ステートメント | 0 |


## ❌ 失敗したテスト

### 1. test_get_public_articles_success
- **クラス**: tests.test_article_router.TestPublicArticlesEndpoint
- **ステータス**: failed
- **実行時間**: 0.003秒
- **失敗メッセージ**: fastapi.exceptions.HTTPException: 500: 記事の取得に失敗しました
```
routers/article.py:408: in get_public_articles
    for article in public_articles:
E   TypeError: 'Mock' object is not iterable

During handling of the above exception, another exception occurred:
tests/test_article_router.py:633: in test_get_public_articles_success
    result = await get_public_articles(mock_db)
routers/article.py:428: in get_public_articles
    raise HTTPException(
E   fastapi.exceptions.HTTPException: 500: 記事の取得に失敗しました
```

### 2. test_get_public_articles_with_limit
- **クラス**: tests.test_article_router.TestPublicArticlesEndpoint
- **ステータス**: failed
- **実行時間**: 0.003秒
- **失敗メッセージ**: fastapi.exceptions.HTTPException: 500: 記事の取得に失敗しました
```
routers/article.py:408: in get_public_articles
    for article in public_articles:
E   TypeError: 'Mock' object is not iterable

During handling of the above exception, another exception occurred:
tests/test_article_router.py:660: in test_get_public_articles_with_limit
    result = await get_public_articles(mock_db, limit=3)
routers/article.py:428: in get_public_articles
    raise HTTPException(
E   fastapi.exceptions.HTTPException: 500: 記事の取得に失敗しました
```

### 3. test_get_public_articles_with_skip
- **クラス**: tests.test_article_router.TestPublicArticlesEndpoint
- **ステータス**: failed
- **実行時間**: 0.003秒
- **失敗メッセージ**: fastapi.exceptions.HTTPException: 500: 記事の取得に失敗しました
```
routers/article.py:408: in get_public_articles
    for article in public_articles:
E   TypeError: 'Mock' object is not iterable

During handling of the above exception, another exception occurred:
tests/test_article_router.py:685: in test_get_public_articles_with_skip
    result = await get_public_articles(mock_db, skip=2)
routers/article.py:428: in get_public_articles
    raise HTTPException(
E   fastapi.exceptions.HTTPException: 500: 記事の取得に失敗しました
```

### 4. test_search_public_articles_success
- **クラス**: tests.test_article_router.TestSearchPublicArticlesEndpoint
- **ステータス**: failed
- **実行時間**: 0.003秒
- **失敗メッセージ**: fastapi.exceptions.HTTPException: 500: 記事検索に失敗しました
```
routers/article.py:504: in search_public_articles
    for article in search_results:
E   TypeError: 'Mock' object is not iterable

During handling of the above exception, another exception occurred:
tests/test_article_router.py:742: in test_search_public_articles_success
    result = await search_public_articles("検索", mock_db)
routers/article.py:519: in search_public_articles
    raise HTTPException(
E   fastapi.exceptions.HTTPException: 500: 記事検索に失敗しました
```

### 5. test_search_public_articles_japanese_keywords
- **クラス**: tests.test_article_router.TestSearchPublicArticlesEndpoint
- **ステータス**: failed
- **実行時間**: 0.003秒
- **失敗メッセージ**: fastapi.exceptions.HTTPException: 500: 記事検索に失敗しました
```
routers/article.py:504: in search_public_articles
    for article in search_results:
E   TypeError: 'Mock' object is not iterable

During handling of the above exception, another exception occurred:
tests/test_article_router.py:770: in test_search_public_articles_japanese_keywords
    result = await search_public_articles("%E6%A4%9C%E7%B4%A2", mock_db)
routers/article.py:519: in search_public_articles
    raise HTTPException(
E   fastapi.exceptions.HTTPException: 500: 記事検索に失敗しました
```

### 6. test_search_public_articles_multiple_keywords
- **クラス**: tests.test_article_router.TestSearchPublicArticlesEndpoint
- **ステータス**: failed
- **実行時間**: 0.003秒
- **失敗メッセージ**: fastapi.exceptions.HTTPException: 500: 記事検索に失敗しました
```
routers/article.py:504: in search_public_articles
    for article in search_results:
E   TypeError: 'Mock' object is not iterable

During handling of the above exception, another exception occurred:
tests/test_article_router.py:795: in test_search_public_articles_multiple_keywords
    result = await search_public_articles("検索 キーワード", mock_db)
routers/article.py:519: in search_public_articles
    raise HTTPException(
E   fastapi.exceptions.HTTPException: 500: 記事検索に失敗しました
```


## 📁 ファイル別カバレッジ

| ファイル | カバレッジ | ステートメント | カバー済み | 未カバー |
|----------|------------|----------------|-----------|----------|
| custom_token.py | 100.0% | 94 | 94 | 0 |
| database.py | 95.5% | 89 | 85 | 4 |
| exceptions.py | 100.0% | 12 | 12 | 0 |
| hashing.py | 77.8% | 9 | 7 | 2 |
| logger/__init__.py | 100.0% | 0 | 0 | 0 |
| logger/custom_logger.py | 100.0% | 21 | 21 | 0 |
| main.py | 92.9% | 42 | 39 | 3 |
| models.py | 97.3% | 37 | 36 | 1 |
| oauth2.py | 100.0% | 37 | 37 | 0 |
| routers/__init__.py | 100.0% | 0 | 0 | 0 |
| routers/article.py | 92.8% | 152 | 141 | 11 |
| routers/auth.py | 100.0% | 124 | 124 | 0 |
| routers/user.py | 99.0% | 201 | 199 | 2 |
| schemas.py | 100.0% | 89 | 89 | 0 |
| utils/__init__.py | 100.0% | 0 | 0 | 0 |
| utils/email_sender.py | 100.0% | 113 | 113 | 0 |
| utils/email_validator.py | 100.0% | 23 | 23 | 0 |

## 📎 生成ファイル
- **JUnit XML**: test_results_20250606_122329.xml
- **カバレッジJSON**: coverage_20250606_122329.json
- **HTMLカバレッジ**: htmlcov_20250606_122329/
