# テスト実行レポート

## 📊 基本情報
- **実行日時**: 2025-06-05T21:11:28.004126
- **テストID**: 20250605_211128
- **テスト対象**: test_custom_logger
- **テストファイル**: tests/test_custom_logger.py

## 🧪 テスト結果サマリー

| 項目 | 値 |
|------|-----|
| 総テスト数 | 16 |
| 成功 | 15 |
| 失敗 | 1 |
| エラー | 0 |
| スキップ | 0 |
| 成功率 | 93.75% |
| 実行時間 | 0.962秒 |

## 📈 カバレッジ結果

| 項目 | 値 |
|------|-----|
| 全体カバレッジ | 3.67% |
| 総ステートメント数 | 3786 |
| カバー済みステートメント | 139 |
| 未カバーステートメント | 3647 |
| 除外ステートメント | 0 |


## ❌ 失敗したテスト

### 1. test_log_directory_creation
- **クラス**: tests.test_custom_logger.TestCustomLoggerConfiguration
- **ステータス**: failed
- **実行時間**: 0.005秒
- **失敗メッセージ**: AssertionError: Expected 'mkdir' to be called once. Called 0 times.
```
tests/test_custom_logger.py:29: in test_log_directory_creation
    mock_log_dir.mkdir.assert_called_once_with(parents=True, exist_ok=True)
/opt/homebrew/Cellar/python@3.11/3.11.11/Frameworks/Python.framework/Versions/3.11/lib/python3.11/unittest/mock.py:950: in assert_called_once_with
    raise AssertionError(msg)
E   AssertionError: Expected 'mkdir' to be called once. Called 0 times.
```


## 📁 ファイル別カバレッジ

| ファイル | カバレッジ | ステートメント | カバー済み | 未カバー |
|----------|------------|----------------|-----------|----------|
| custom_token.py | 0.0% | 94 | 0 | 94 |
| database.py | 0.0% | 89 | 0 | 89 |
| exceptions.py | 0.0% | 12 | 0 | 12 |
| hashing.py | 0.0% | 9 | 0 | 9 |
| logger/__init__.py | 100.0% | 0 | 0 | 0 |
| logger/custom_logger.py | 100.0% | 21 | 21 | 0 |
| main.py | 0.0% | 42 | 0 | 42 |
| models.py | 0.0% | 37 | 0 | 37 |
| oauth2.py | 0.0% | 37 | 0 | 37 |
| routers/__init__.py | 100.0% | 0 | 0 | 0 |
| routers/article.py | 0.0% | 152 | 0 | 152 |
| routers/auth.py | 0.0% | 98 | 0 | 98 |
| routers/user.py | 0.0% | 201 | 0 | 201 |
| schemas.py | 0.0% | 89 | 0 | 89 |
| test_runner_with_history.py | 0.0% | 223 | 0 | 223 |
| tests/__init__.py | 100.0% | 0 | 0 | 0 |
| tests/bug_tracker.py | 0.0% | 200 | 0 | 200 |
| tests/test_article_router.py | 0.0% | 252 | 0 | 252 |
| tests/test_auth_router.py | 0.0% | 175 | 0 | 175 |
| tests/test_custom_logger.py | 90.8% | 130 | 118 | 12 |
| tests/test_custom_token.py | 0.0% | 191 | 0 | 191 |
| tests/test_database.py | 0.0% | 113 | 0 | 113 |
| tests/test_email_sender.py | 100.0% | 0 | 0 | 0 |
| tests/test_email_validator.py | 100.0% | 0 | 0 | 0 |
| tests/test_exceptions.py | 0.0% | 150 | 0 | 150 |
| tests/test_hashing.py | 100.0% | 0 | 0 | 0 |
| tests/test_integration.py | 100.0% | 0 | 0 | 0 |
| tests/test_main.py | 0.0% | 169 | 0 | 169 |
| tests/test_models.py | 0.0% | 165 | 0 | 165 |
| tests/test_oauth2.py | 0.0% | 138 | 0 | 138 |
| tests/test_routers_corrected.py | 100.0% | 0 | 0 | 0 |
| tests/test_schemas.py | 0.0% | 196 | 0 | 196 |
| tests/test_user_deletion_integration.py | 0.0% | 121 | 0 | 121 |
| tests/test_user_router.py | 0.0% | 525 | 0 | 525 |
| update_final_success.py | 0.0% | 21 | 0 | 21 |
| utils/__init__.py | 100.0% | 0 | 0 | 0 |
| utils/email_sender.py | 0.0% | 113 | 0 | 113 |
| utils/email_validator.py | 0.0% | 23 | 0 | 23 |

## 📎 生成ファイル
- **JUnit XML**: test_results_20250605_211128.xml
- **カバレッジJSON**: coverage_20250605_211128.json
- **HTMLカバレッジ**: htmlcov_20250605_211128/
